<?xml version="1.0" encoding="UTF-8"?>
<testng-results ignored="0" total="4" passed="0" failed="2" skipped="2">
  <reporter-output>
  </reporter-output>
  <suite started-at="2019-05-01T19:56:17Z" name="Suite1" finished-at="2019-05-01T19:56:47Z" duration-ms="30076">
    <groups>
      <group name="group1">
        <method signature="HomePageSteps.VerifyLogin()[pri:1, instance:page.steps.HomePageSteps@3a44431a]" name="VerifyLogin" class="page.steps.HomePageSteps"/>
        <method signature="HomePageSteps.VerifyLogin()[pri:1, instance:page.steps.DashBoardPageSteps@428640fa]" name="VerifyLogin" class="page.steps.HomePageSteps"/>
      </group> <!-- group1 -->
    </groups>
    <test started-at="2019-05-01T19:56:17Z" name="Test1" finished-at="2019-05-01T19:56:34Z" duration-ms="16755">
      <class name="page.steps.HomePageSteps">
        <test-method is-config="true" signature="InitialStartUp()[pri:0, instance:page.steps.HomePageSteps@3a44431a]" started-at="2019-05-01T19:56:17Z" name="InitialStartUp" finished-at="2019-05-01T19:56:22Z" duration-ms="5033" status="PASS">
          <reporter-output>
          </reporter-output>
        </test-method> <!-- InitialStartUp -->
        <test-method signature="VerifyLogin()[pri:1, instance:page.steps.HomePageSteps@3a44431a]" started-at="2019-05-01T19:56:22Z" name="VerifyLogin" finished-at="2019-05-01T19:56:32Z" duration-ms="10496" status="FAIL">
          <exception class="java.lang.AssertionError">
            <message>
              <![CDATA[Login Success expected [ut] but found [Logout]]]>
            </message>
            <full-stacktrace>
              <![CDATA[java.lang.AssertionError: Login Success expected [ut] but found [Logout]
at org.testng.Assert.fail(Assert.java:96)
at org.testng.Assert.failNotEquals(Assert.java:776)
at org.testng.Assert.assertEqualsImpl(Assert.java:137)
at org.testng.Assert.assertEquals(Assert.java:118)
at org.testng.Assert.assertEquals(Assert.java:453)
at page.steps.HomePageSteps.VerifyLogin(HomePageSteps.java:34)
at java.base/jdk.internal.reflect.NativeMethodAccessorImpl.invoke0(Native Method)
at java.base/jdk.internal.reflect.NativeMethodAccessorImpl.invoke(NativeMethodAccessorImpl.java:62)
at java.base/jdk.internal.reflect.DelegatingMethodAccessorImpl.invoke(DelegatingMethodAccessorImpl.java:43)
at java.base/java.lang.reflect.Method.invoke(Method.java:566)
at org.testng.internal.MethodInvocationHelper.invokeMethod(MethodInvocationHelper.java:124)
at org.testng.internal.Invoker.invokeMethod(Invoker.java:583)
at org.testng.internal.Invoker.invokeTestMethod(Invoker.java:719)
at org.testng.internal.Invoker.invokeTestMethods(Invoker.java:989)
at org.testng.internal.TestMethodWorker.invokeTestMethods(TestMethodWorker.java:125)
at org.testng.internal.TestMethodWorker.run(TestMethodWorker.java:109)
at org.testng.TestRunner.privateRun(TestRunner.java:648)
at org.testng.TestRunner.run(TestRunner.java:505)
at org.testng.SuiteRunner.runTest(SuiteRunner.java:455)
at org.testng.SuiteRunner.runSequentially(SuiteRunner.java:450)
at org.testng.SuiteRunner.privateRun(SuiteRunner.java:415)
at org.testng.SuiteRunner.run(SuiteRunner.java:364)
at org.testng.SuiteRunnerWorker.runSuite(SuiteRunnerWorker.java:52)
at org.testng.SuiteRunnerWorker.run(SuiteRunnerWorker.java:84)
at org.testng.TestNG.runSuitesSequentially(TestNG.java:1208)
at org.testng.TestNG.runSuitesLocally(TestNG.java:1137)
at org.testng.TestNG.runSuites(TestNG.java:1049)
at org.testng.TestNG.run(TestNG.java:1017)
at org.testng.remote.AbstractRemoteTestNG.run(AbstractRemoteTestNG.java:115)
at org.testng.remote.RemoteTestNG.initAndRun(RemoteTestNG.java:251)
at org.testng.remote.RemoteTestNG.main(RemoteTestNG.java:77)
]]>
            </full-stacktrace>
          </exception> <!-- java.lang.AssertionError -->
          <reporter-output>
          </reporter-output>
        </test-method> <!-- VerifyLogin -->
        <test-method is-config="true" signature="TearDown()[pri:0, instance:page.steps.HomePageSteps@3a44431a]" started-at="2019-05-01T19:56:33Z" name="TearDown" finished-at="2019-05-01T19:56:34Z" duration-ms="604" status="PASS">
          <reporter-output>
          </reporter-output>
        </test-method> <!-- TearDown -->
      </class> <!-- page.steps.HomePageSteps -->
    </test> <!-- Test1 -->
    <test started-at="2019-05-01T19:56:34Z" name="Test2" finished-at="2019-05-01T19:56:47Z" duration-ms="13256">
      <class name="page.steps.DashBoardPageSteps">
        <test-method is-config="true" signature="InitialStartUp()[pri:0, instance:page.steps.DashBoardPageSteps@428640fa]" started-at="2019-05-01T19:56:34Z" name="InitialStartUp" finished-at="2019-05-01T19:56:37Z" duration-ms="3632" status="PASS">
          <reporter-output>
          </reporter-output>
        </test-method> <!-- InitialStartUp -->
        <test-method signature="VerifyLogin()[pri:1, instance:page.steps.DashBoardPageSteps@428640fa]" started-at="2019-05-01T19:56:37Z" name="VerifyLogin" finished-at="2019-05-01T19:56:46Z" duration-ms="8447" status="FAIL">
          <exception class="java.lang.AssertionError">
            <message>
              <![CDATA[Login Success expected [ut] but found [Logout]]]>
            </message>
            <full-stacktrace>
              <![CDATA[java.lang.AssertionError: Login Success expected [ut] but found [Logout]
at org.testng.Assert.fail(Assert.java:96)
at org.testng.Assert.failNotEquals(Assert.java:776)
at org.testng.Assert.assertEqualsImpl(Assert.java:137)
at org.testng.Assert.assertEquals(Assert.java:118)
at org.testng.Assert.assertEquals(Assert.java:453)
at page.steps.HomePageSteps.VerifyLogin(HomePageSteps.java:34)
at java.base/jdk.internal.reflect.NativeMethodAccessorImpl.invoke0(Native Method)
at java.base/jdk.internal.reflect.NativeMethodAccessorImpl.invoke(NativeMethodAccessorImpl.java:62)
at java.base/jdk.internal.reflect.DelegatingMethodAccessorImpl.invoke(DelegatingMethodAccessorImpl.java:43)
at java.base/java.lang.reflect.Method.invoke(Method.java:566)
at org.testng.internal.MethodInvocationHelper.invokeMethod(MethodInvocationHelper.java:124)
at org.testng.internal.Invoker.invokeMethod(Invoker.java:583)
at org.testng.internal.Invoker.invokeTestMethod(Invoker.java:719)
at org.testng.internal.Invoker.invokeTestMethods(Invoker.java:989)
at org.testng.internal.TestMethodWorker.invokeTestMethods(TestMethodWorker.java:125)
at org.testng.internal.TestMethodWorker.run(TestMethodWorker.java:109)
at org.testng.TestRunner.privateRun(TestRunner.java:648)
at org.testng.TestRunner.run(TestRunner.java:505)
at org.testng.SuiteRunner.runTest(SuiteRunner.java:455)
at org.testng.SuiteRunner.runSequentially(SuiteRunner.java:450)
at org.testng.SuiteRunner.privateRun(SuiteRunner.java:415)
at org.testng.SuiteRunner.run(SuiteRunner.java:364)
at org.testng.SuiteRunnerWorker.runSuite(SuiteRunnerWorker.java:52)
at org.testng.SuiteRunnerWorker.run(SuiteRunnerWorker.java:84)
at org.testng.TestNG.runSuitesSequentially(TestNG.java:1208)
at org.testng.TestNG.runSuitesLocally(TestNG.java:1137)
at org.testng.TestNG.runSuites(TestNG.java:1049)
at org.testng.TestNG.run(TestNG.java:1017)
at org.testng.remote.AbstractRemoteTestNG.run(AbstractRemoteTestNG.java:115)
at org.testng.remote.RemoteTestNG.initAndRun(RemoteTestNG.java:251)
at org.testng.remote.RemoteTestNG.main(RemoteTestNG.java:77)
]]>
            </full-stacktrace>
          </exception> <!-- java.lang.AssertionError -->
          <reporter-output>
          </reporter-output>
        </test-method> <!-- VerifyLogin -->
        <test-method signature="GetNumberofUsers()[pri:2, instance:page.steps.DashBoardPageSteps@428640fa]" started-at="2019-05-01T19:56:46Z" name="GetNumberofUsers" depends-on-groups="group1" finished-at="2019-05-01T19:56:46Z" duration-ms="0" status="SKIP">
          <exception class="java.lang.Throwable">
            <message>
              <![CDATA[Method DashBoardPageSteps.GetNumberofUsers()[pri:2, instance:page.steps.DashBoardPageSteps@428640fa] depends on not successfully finished methods in group "group1"]]>
            </message>
            <full-stacktrace>
              <![CDATA[java.lang.Throwable: Method DashBoardPageSteps.GetNumberofUsers()[pri:2, instance:page.steps.DashBoardPageSteps@428640fa] depends on not successfully finished methods in group "group1"
at org.testng.internal.Invoker.invokeTestMethods(Invoker.java:888)
at org.testng.internal.TestMethodWorker.invokeTestMethods(TestMethodWorker.java:125)
at org.testng.internal.TestMethodWorker.run(TestMethodWorker.java:109)
at org.testng.TestRunner.privateRun(TestRunner.java:648)
at org.testng.TestRunner.run(TestRunner.java:505)
at org.testng.SuiteRunner.runTest(SuiteRunner.java:455)
at org.testng.SuiteRunner.runSequentially(SuiteRunner.java:450)
at org.testng.SuiteRunner.privateRun(SuiteRunner.java:415)
at org.testng.SuiteRunner.run(SuiteRunner.java:364)
at org.testng.SuiteRunnerWorker.runSuite(SuiteRunnerWorker.java:52)
at org.testng.SuiteRunnerWorker.run(SuiteRunnerWorker.java:84)
at org.testng.TestNG.runSuitesSequentially(TestNG.java:1208)
at org.testng.TestNG.runSuitesLocally(TestNG.java:1137)
at org.testng.TestNG.runSuites(TestNG.java:1049)
at org.testng.TestNG.run(TestNG.java:1017)
at org.testng.remote.AbstractRemoteTestNG.run(AbstractRemoteTestNG.java:115)
at org.testng.remote.RemoteTestNG.initAndRun(RemoteTestNG.java:251)
at org.testng.remote.RemoteTestNG.main(RemoteTestNG.java:77)
]]>
            </full-stacktrace>
          </exception> <!-- java.lang.Throwable -->
          <reporter-output>
          </reporter-output>
        </test-method> <!-- GetNumberofUsers -->
        <test-method signature="AddUserCheck()[pri:3, instance:page.steps.DashBoardPageSteps@428640fa]" started-at="2019-05-01T19:56:46Z" name="AddUserCheck" depends-on-groups="group1" finished-at="2019-05-01T19:56:46Z" duration-ms="0" status="SKIP">
          <exception class="java.lang.Throwable">
            <message>
              <![CDATA[Method DashBoardPageSteps.AddUserCheck()[pri:3, instance:page.steps.DashBoardPageSteps@428640fa] depends on not successfully finished methods in group "group1"]]>
            </message>
            <full-stacktrace>
              <![CDATA[java.lang.Throwable: Method DashBoardPageSteps.AddUserCheck()[pri:3, instance:page.steps.DashBoardPageSteps@428640fa] depends on not successfully finished methods in group "group1"
at org.testng.internal.Invoker.invokeTestMethods(Invoker.java:888)
at org.testng.internal.TestMethodWorker.invokeTestMethods(TestMethodWorker.java:125)
at org.testng.internal.TestMethodWorker.run(TestMethodWorker.java:109)
at org.testng.TestRunner.privateRun(TestRunner.java:648)
at org.testng.TestRunner.run(TestRunner.java:505)
at org.testng.SuiteRunner.runTest(SuiteRunner.java:455)
at org.testng.SuiteRunner.runSequentially(SuiteRunner.java:450)
at org.testng.SuiteRunner.privateRun(SuiteRunner.java:415)
at org.testng.SuiteRunner.run(SuiteRunner.java:364)
at org.testng.SuiteRunnerWorker.runSuite(SuiteRunnerWorker.java:52)
at org.testng.SuiteRunnerWorker.run(SuiteRunnerWorker.java:84)
at org.testng.TestNG.runSuitesSequentially(TestNG.java:1208)
at org.testng.TestNG.runSuitesLocally(TestNG.java:1137)
at org.testng.TestNG.runSuites(TestNG.java:1049)
at org.testng.TestNG.run(TestNG.java:1017)
at org.testng.remote.AbstractRemoteTestNG.run(AbstractRemoteTestNG.java:115)
at org.testng.remote.RemoteTestNG.initAndRun(RemoteTestNG.java:251)
at org.testng.remote.RemoteTestNG.main(RemoteTestNG.java:77)
]]>
            </full-stacktrace>
          </exception> <!-- java.lang.Throwable -->
          <reporter-output>
          </reporter-output>
        </test-method> <!-- AddUserCheck -->
        <test-method is-config="true" signature="TearDown()[pri:0, instance:page.steps.DashBoardPageSteps@428640fa]" started-at="2019-05-01T19:56:46Z" name="TearDown" finished-at="2019-05-01T19:56:47Z" duration-ms="597" status="PASS">
          <reporter-output>
          </reporter-output>
        </test-method> <!-- TearDown -->
      </class> <!-- page.steps.DashBoardPageSteps -->
    </test> <!-- Test2 -->
  </suite> <!-- Suite1 -->
</testng-results>
